<?xml version="1.0"?>
<robot name="myfirst">
  <link name="base_link">
    <visual>
      <geometry>
        <box size="0.1 .1 .9"/>
      </geometry>
      <material name="black">
          <color rgba="1 1 0 1"/>
      </material> 
    </visual>
  </link>

  <link name="link_2">
    <visual>
      <geometry>
        <box size="0.1 .1 .9"/>
      </geometry>
      <origin rpy="0 1.57075 0" xyz="0.3 0 0.35"/>
    </visual>
  </link>

  <link name="link_3">
    <visual>
      <geometry>
        <box size="0.1 .1 .5"/>
      </geometry>
      <origin rpy="1.57075 1.57075 0" xyz="0.3 0 0.25"/>
    </visual>
  </link>
  <link name="link_4">
    <visual>
      <geometry>
        <box size="0.1 .1 .1"/>
      </geometry>
      <origin rpy="1.57075 1.57075 0" xyz="0.3 0 0.15"/>
      <material name="black">
          <color rgba="1 1 0 1"/>
      </material>
    </visual>
  </link>

  <joint name="base_to_link_2" type="prismatic">
    <parent link="base_link"/>
    <child link="link_2"/>
    <origin xyz="0 0 0"/>
    <axis xyz="0 0 1"/>
    <limit effort="100" velocity="100" lower="-0.6" upper="0.03"/>
  </joint>

  <joint name="link_2_to_link_3" type="prismatic">
    <parent link="link_2"/>
    <child link="link_3"/>
    <oringin xyz="0 0 0"/>
    <limit effort="100" velocity="100" lower="-0.20" upper="0.2"/>
  </joint>

  <joint name="link_3_to_link_4" type="prismatic">
    <parent link="link_3"/>
    <child link="link_4"/>
    <oringin xyz="0 0 0"/>
    <axis xyz="0 1 0"/>
    <limit effort="100" velocity="100" lower="-0.20" upper="0.2"/>
  </joint>
</robot>


